Workbook

Sheet Raw Data
A1: Application_ID | B1: Citizen_Name | C1: District | D1: Service_Type | E1: Application_Channel | F1: Application_Date | G1: Status | H1: Processing_Days | I1: Service_Fee | J1: Satisfaction_Rating | L1: Colour legend
A2: EG2026-001 | B2: Santosh Salunkhe | C2: Pune | D2: Birth Certificate | E2: Online | F2: 46023 | G2: Approved | H2: 3 | I2: 50 | J2: 5 | L2: Yellow = missing / inconsistent value
A3: EG2026-002 | B3: Jyoti Shinde | C3: Sangli | D3: Scholarship Application | E3: Online | F3: 46025 | G3: Approved | H3: 10 | I3: 0 | J3: 5 | L3: Orange = duplicate record
A4: EG2026-003 | B4: Ajay Bhosale | C4: Pune | D4: Residence Certificate | E4: Online | F4: 46026 | G4: Rejected | H4: 3 | I4: 30 | J4: 4
A5: EG2026-004 | B5: Sachin Bhosale | C5: Kolhapur | D5: Scholarship Application | E5: CSC Center | F5: 46029 | G5: Approved | H5: 15 | I5: 0 | J5: 3
A6: EG2026-005 | B6: Suresh Sawant | C6: Kolhapur | D6: Income Certificate | E6: Government Office | F6: 46040 | G6: Rejected | H6: 6 | I6: 40 | J6: 2
A7: EG2026-006 | B7: Omkar Chavan | C7: Sangli | D7: Birth Certificate | E7: Online | F7: 46054 | G7: Approved | H7: 5 | I7: 40 | J7: 4
A8: EG2026-006 | B8: Omkar Chavan | C8: Sangli | D8: Birth Certificate | E8: Online | F8: 46054 | G8: Approved | H8: 5 | I8: 40 | J8: 4
A9: EG2026-007 | B9: Yogesh Mohite | C9: Satara | D9: Birth Certificate | E9: Online | F9: 46055 | G9: Approved | H9: 3 | I9: 45 | J9: 4
A10: EG2026-008 | B10: Sachin Kamble | C10: kolhapur | D10: Property Tax | E10: Online | F10: 46055 | G10: Approved | H10: 2 | I10: 3000 | J10: 4
A11: EG2026-009 | B11: Suresh Kale | C11: Satara | D11: Residence Certificate | E11: Online | F11: 46055 | G11: Approved | H11: 6 | I11: 35 | J11: 5
A12: EG2026-010 | B12: Kavita Kamble | C12: Satara | D12: Residence Certificate | E12: Government Office | F12: 46061 | G12: Approved | H12: 6 | I12: 35 | J12: 5
A13: EG2026-011 | B13: Meena Desai | C13: Kolhapur | D13: Income Certificate | E13: CSC Center | F13: 46062 | G13: Approved | H13: 5 | I13: 30 | J13: 5
A14: EG2026-012 | B14: Santosh More | C14: Sangli | D14: Income Certificate | E14: Online | F14: 46062 | G14: Approved | H14: 6 | I14: 35 | J14: 4
A15: EG2026-013 | B15: Sneha Mane | C15: Pune | D15: Residence Certificate | E15: Government Office | F15: 46065 | G15: Approved | I15: 35 | J15: 3
A16: EG2026-014 | B16: Prashant Kulkarni | C16: Solapur | D16: Income Certificate | E16: Online | F16: 46066 | G16: Approved | H16: 5 | I16: 30 | J16: 5
A17: EG2026-015 | B17: Kiran Sawant | C17: Pune | D17: Income Certificate | E17: CSC Center | F17: 46070 | G17: Approved | H17: 4 | I17: 35 | J17: 3
A18: EG2026-016 | B18: Pallavi Desai | C18: Sangli | D18: Property Tax | E18: CSC Center | F18: 46070 | G18: Approved | H18: 4 | I18: 600 | J18: 3
A19: EG2026-017 | B19: Rohan Mohite | C19: Sangli | D19: Scholarship Application | E19: Government Office | F19: 46075 | G19: Approved | H19: 11 | I19: 0 | J19: 4
A20: EG2026-018 | B20: Rohan Salunkhe | C20: Solapur | D20: Property Tax | E20: Online | F20: 46076 | G20: Approved | H20: 4 | I20: 1500 | J20: 5
A21: EG2026-019 | B21: Swati Thorat | C21: Sangli | D21: Income Certificate | E21: CSC Center | F21: 46077 | G21: Approved | H21: 6 | I21: 35 | J21: 5
A22: EG2026-020 | B22: Ajay Gaikwad | C22: Satara | D22: Caste Certificate | E22: CSC Center | F22: 46079 | G22: Approved | H22: 10 | I22: 30
A23: EG2026-021 | B23: Madhuri Kale | C23: Solapur | D23: Senior Citizen Certificate | E23: CSC Center | F23: 46079 | G23: Approved | H23: 6 | I23: 25 | J23: 4
A24: EG2026-022 | B24: Priya Yadav | C24: Satara | D24: Scholarship Application | E24: CSC Center | F24: 46080 | G24: Approved | H24: 7 | I24: 0 | J24: 4
A25: EG2026-023 | B25: Pooja Sawant | C25: Kolhapur | D25: Residence Certificate | E25: CSC Center | F25: 46082 | G25: Approved | H25: 5 | I25: 30 | J25: 5
A26: EG2026-024 | B26: Prashant Mane | C26: Sangli | D26: Birth Certificate | E26: Online | F26: 46085 | G26: Approved | H26: 5 | I26: 50 | J26: 5
A27: EG2026-025 | B27: Mahesh Sawant | C27: Sangli | D27: Residence Certificate | E27: Government Office | F27: 46090 | G27: Approved | H27: 9 | I27: 30 | J27: 3
A28: EG2026-026 | B28: Yogesh Jadhav | C28: Kolhapur | E28: Online | F28: 46091 | G28: Rejected | H28: 4 | I28: 40 | J28: 1
A29: EG2026-027 | B29: Suresh Patil | C29: Kolhapur | D29: Property Tax | E29: Online | F29: 46092 | G29: Approved | H29: 3 | I29: 2200 | J29: 3
A30: EG2026-028 | B30: Pallavi Thorat | C30: Pune | D30: Scholarship Application | E30: Government Office | F30: 46094 | G30: Approved | H30: 10 | I30: 0 | J30: 5
A31: EG2026-029 | B31: Rekha Chavan | C31: Kolhapur | D31: Income Certificate | E31: Government Office | F31: 46100 | G31: Approved | H31: 11 | I31: 30 | J31: 3
A32: EG2026-029 | B32: Rekha Chavan | C32: Kolhapur | D32: Income Certificate | E32: Government Office | F32: 46100 | G32: Approved | H32: 11 | I32: 30 | J32: 3
A33: EG2026-030 | B33: Rekha Kamble | C33: Sangli | D33: Income Certificate | E33: CSC Center | F33: 46102 | G33: Approved | H33: 7 | I33: 30 | J33: 3
A34: EG2026-031 | B34: Yogesh Desai | C34: Kolhapur | D34: Residence Certificate | E34: CSC Center | F34: 46105 | G34: Pending | H34: 4 | I34: 25 | J34: 3
A35: EG2026-032 | B35: Rekha Kale | C35: Pune | D35: Water Connection | E35: Government Office | F35: 46105 | G35: Approved | H35: 15 | I35: 2000 | J35: 5
A36: EG2026-033 | B36: Shital Salunkhe | C36: Pune | D36: Caste Certificate | E36: Online | F36: 46106 | G36: Approved | H36: 9 | I36: 30 | J36: 4
A37: EG2026-034 | B37: Vijay Joshi | C37: SANGLI | D37: Birth Certificate | E37: Online | F37: 46107 | G37: Approved | H37: 3 | I37: 30 | J37: 4
A38: EG2026-035 | B38: Dattatray Gaikwad | C38: Solapur | D38: Birth Certificate | E38: Online | F38: 46117 | G38: Approved | H38: 3 | I38: 35 | J38: 5
A39: EG2026-036 | B39: Sunita Pawar | C39: Satara | D39: Income Certificate | E39: Government Office | F39: 46123 | G39: Approved | H39: 11 | I39: 35 | J39: 3
A40: EG2026-037 | B40: Kiran Mane | C40: Solapur | D40: Birth Certificate | E40: CSC Center | F40: 46123 | G40: Approved | H40: 6 | I40: 45 | J40: 3
...

Sheet Cleaned Data
A1: Application_ID | B1: Citizen_Name | C1: District | D1: Service_Type | E1: Application_Channel | F1: Application_Date | G1: Status | H1: Processing_Days | I1: Service_Fee | J1: Satisfaction_Rating | L1: Green = value filled during cleaning
A2: EG2026-001 | B2: Santosh Salunkhe | C2: Pune | D2: Birth Certificate | E2: Online | F2: 46023 | G2: Approved | H2: 3 | I2: 50 | J2: 5
A3: EG2026-002 | B3: Jyoti Shinde | C3: Sangli | D3: Scholarship Application | E3: Online | F3: 46025 | G3: Approved | H3: 10 | I3: 0 | J3: 5
A4: EG2026-003 | B4: Ajay Bhosale | C4: Pune | D4: Residence Certificate | E4: Online | F4: 46026 | G4: Rejected | H4: 3 | I4: 30 | J4: 4
A5: EG2026-004 | B5: Sachin Bhosale | C5: Kolhapur | D5: Scholarship Application | E5: CSC Center | F5: 46029 | G5: Approved | H5: 15 | I5: 0 | J5: 3
A6: EG2026-005 | B6: Suresh Sawant | C6: Kolhapur | D6: Income Certificate | E6: Government Office | F6: 46040 | G6: Rejected | H6: 6 | I6: 40 | J6: 2
A7: EG2026-006 | B7: Omkar Chavan | C7: Sangli | D7: Birth Certificate | E7: Online | F7: 46054 | G7: Approved | H7: 5 | I7: 40 | J7: 4
A8: EG2026-007 | B8: Yogesh Mohite | C8: Satara | D8: Birth Certificate | E8: Online | F8: 46055 | G8: Approved | H8: 3 | I8: 45 | J8: 4
A9: EG2026-008 | B9: Sachin Kamble | C9: Kolhapur | D9: Property Tax | E9: Online | F9: 46055 | G9: Approved | H9: 2 | I9: 3000 | J9: 4
A10: EG2026-009 | B10: Suresh Kale | C10: Satara | D10: Residence Certificate | E10: Online | F10: 46055 | G10: Approved | H10: 6 | I10: 35 | J10: 5
A11: EG2026-010 | B11: Kavita Kamble | C11: Satara | D11: Residence Certificate | E11: Government Office | F11: 46061 | G11: Approved | H11: 6 | I11: 35 | J11: 5
A12: EG2026-011 | B12: Meena Desai | C12: Kolhapur | D12: Income Certificate | E12: CSC Center | F12: 46062 | G12: Approved | H12: 5 | I12: 30 | J12: 5
A13: EG2026-012 | B13: Santosh More | C13: Sangli | D13: Income Certificate | E13: Online | F13: 46062 | G13: Approved | H13: 6 | I13: 35 | J13: 4
... A91: EG2026-090 | B91: Jyoti Joshi | C91: Pune | D91: Property Tax | E91: CSC Center | F91: 46262 | G91: Approved | H91: 3 | I91: 2200 | J91: 4

Sheet Data Cleaning Summary
A1: Data Cleaning Summary
A3: Item | B3: Value | C3: Remark
A4: Original Records | B4: =COUNTA('Raw Data'!A2:A95) -> 94 | C4: Rows in raw_e_governance_data.csv
A5: Records After Cleaning | B5: =COUNTA('Cleaned Data'!A2:A91) -> 90 | C5: Rows in cleaned_e_governance_data.csv
A6: Duplicate Records Removed | B6: =B4-B5 -> 4 | C6: Same Application_ID and same details repeated: EG2026-006, EG2026-029, EG2026-047, EG2026-072
A7: Missing Values Found - Service_Type | B7: =COUNTBLANK('Raw Data'!D2:D95) -> 2 | C7: Filled with mode (most frequent service)
A8: Missing Values Found - Processing_Days | B8: =COUNTBLANK('Raw Data'!H2:H95) -> 3 | C8: Filled with median
A9: Missing Values Found - Satisfaction_Rating | B9: =COUNTBLANK('Raw Data'!J2:J95) -> 3 | C9: Filled with median
A10: Total Missing Values Found | B10: =SUM(B7:B9) -> 8
A11: Missing Values Remaining After Cleaning | B11: =COUNTBLANK('Cleaned Data'!A2:J91) -> 0 | C11: Should be 0
A12: Value used: Mode of Service_Type | B12: Property Tax | C12: Calculated on the data after removing duplicates
A13: Value used: Median of Processing_Days | B13: 6 | C13: Calculated on the data after removing duplicates
A14: Value used: Median of Satisfaction_Rating | B14: 4 | C14: Calculated on the data after removing duplicates
A15: Inconsistent District Values Corrected | B15: 4 | C15: kolhapur -> Kolhapur, SANGLI -> Sangli, "Pune " -> Pune, Sholapur -> Solapur

Sheet Calculations
A1: KPI Calculations (all formulas use the Cleaned Data sheet)
A3: KPI | B3: Value | C3: Formula meaning
A4: Total Applications | B4: =COUNTA('Cleaned Data'!$A$2:$A$91) -> 90 | C4: Count of Application_ID
A5: Approved Applications | B5: =COUNTIF('Cleaned Data'!$G$2:$G$91,"Approved") -> 66 | C5: Status = Approved
A6: Rejected Applications | B6: =COUNTIF('Cleaned Data'!$G$2:$G$91,"Rejected") -> 7 | C6: Status = Rejected
A7: Pending Applications | B7: =COUNTIF('Cleaned Data'!$G$2:$G$91,"Pending") -> 17 | C7: Status = Pending
A8: Approval Rate (%) | B8: =ROUND(B5/B4*100,1) -> 73.3 | C8: Approved / Total x 100
A9: Average Processing Days | B9: =ROUND(AVERAGE('Cleaned Data'!$H$2:$H$91),1) -> 7 | C9: Average of Processing_Days
A10: Average Satisfaction Rating | B10: =ROUND(AVERAGE('Cleaned Data'!$J$2:$J$91),2) -> 3.73 | C10: Average of Satisfaction_Rating
A11: Total Service Fee Collected (Rs.) | B11: =SUM('Cleaned Data'!$I$2:$I$91) -> 37345 | C11: Sum of Service_Fee

Sheet Chart Data
A1: Chart Data (formulas)
A3: 1. Applications by District
A4: District | B4: Applications
A5: Sangli | B5: =COUNTIF('Cleaned Data'!$C$2:$C$91,A5) -> 26
A6: Pune | B6: =COUNTIF('Cleaned Data'!$C$2:$C$91,A6) -> 22
A7: Kolhapur | B7: =COUNTIF('Cleaned Data'!$C$2:$C$91,A7) -> 19
A8: Solapur | B8: =COUNTIF('Cleaned Data'!$C$2:$C$91,A8) -> 12
A9: Satara | B9: =COUNTIF('Cleaned Data'!$C$2:$C$91,A9) -> 11
A12: 2. Application Status
A13: Status | B13: Applications
A14: Approved | B14: =COUNTIF('Cleaned Data'!$G$2:$G$91,A14) -> 66
A15: Rejected | B15: =COUNTIF('Cleaned Data'!$G$2:$G$91,A15) -> 7
A16: Pending | B16: =COUNTIF('Cleaned Data'!$G$2:$G$91,A16) -> 17
A18: 3. Monthly Applications
A19: Month | B19: Applications
A20: Jan 2026 | B20: =COUNTIFS('Cleaned Data'!$F$2:$F$91,">="&DATE(2026,1,1),'Cleaned Data'!$F$2:$F$91,"<"&DATE(2026,2,1)) -> 5
A21: Feb 2026 | B21: =COUNTIFS('Cleaned Data'!$F$2:$F$91,">="&DATE(2026,2,1),'Cleaned Data'!$F$2:$F$91,"<"&DATE(2026,3,1)) -> 17
A22: Mar 2026 | B22: =COUNTIFS('Cleaned Data'!$F$2:$F$91,">="&DATE(2026,3,1),'Cleaned Data'!$F$2:$F$91,"<"&DATE(2026,4,1)) -> 12
A23: Apr 2026 | B23: =COUNTIFS('Cleaned Data'!$F$2:$F$91,">="&DATE(2026,4,1),'Cleaned Data'!$F$2:$F$91,"<"&DATE(2026,5,1)) -> 7
A24: May 2026 | B24: =COUNTIFS('Cleaned Data'!$F$2:$F$91,">="&DATE(2026,5,1),'Cleaned Data'!$F$2:$F$91,"<"&DATE(2026,6,1)) -> 12
A25: Jun 2026 | B25: =COUNTIFS('Cleaned Data'!$F$2:$F$91,">="&DATE(2026,6,1),'Cleaned Data'!$F$2:$F$91,"<"&DATE(2026,7,1)) -> 7
A26: Jul 2026 | B26: =COUNTIFS('Cleaned Data'!$F$2:$F$91,">="&DATE(2026,7,1),'Cleaned Data'!$F$2:$F$91,"<"&DATE(2026,8,1)) -> 12
A27: Aug 2026 | B27: =COUNTIFS('Cleaned Data'!$F$2:$F$91,">="&DATE(2026,8,1),'Cleaned Data'!$F$2:$F$91,"<"&DATE(2026,9,1)) -> 18
A30: 4. Applications by Service Type
A31: Service Type | B31: Applications
A32: Property Tax | B32: =COUNTIF('Cleaned Data'!$D$2:$D$91,A32) -> 21
A33: Residence Certificate | B33: =COUNTIF('Cleaned Data'!$D$2:$D$91,A33) -> 16
A34: Scholarship Application | B34: =COUNTIF('Cleaned Data'!$D$2:$D$91,A34) -> 12
A35: Income Certificate | B35: =COUNTIF('Cleaned Data'!$D$2:$D$91,A35) -> 12
A36: Caste Certificate | B36: =COUNTIF('Cleaned Data'!$D$2:$D$91,A36) -> 10
A37: Birth Certificate | B37: =COUNTIF('Cleaned Data'!$D$2:$D$91,A37) -> 9
A38: Senior Citizen Certificate | B38: =COUNTIF('Cleaned Data'!$D$2:$D$91,A38) -> 6
A39: Water Connection | B39: =COUNTIF('Cleaned Data'!$D$2:$D$91,A39) -> 4
A41: 5. Average Processing Days by Service
A42: Service Type | B42: Avg Days
A43: Property Tax | B43: =ROUND(AVERAGEIF('Cleaned Data'!$D$2:$D$91,A43,'Cleaned Data'!$H$2:$H$91),1) -> 4.4
A44: Residence Certificate | B44: =ROUND(AVERAGEIF('Cleaned Data'!$D$2:$D$91,A44,'Cleaned Data'!$H$2:$H$91),1) -> 5.8
A45: Scholarship Application | B45: =ROUND(AVERAGEIF('Cleaned Data'!$D$2:$D$91,A45,'Cleaned Data'!$H$2:$H$91),1) -> 11.8
A46: Income Certificate | B46: =ROUND(AVERAGEIF('Cleaned Data'!$D$2:$D$91,A46,'Cleaned Data'!$H$2:$H$91),1) -> 6.7
A47: Caste Certificate | B47: =ROUND(AVERAGEIF('Cleaned Data'!$D$2:$D$91,A47,'Cleaned Data'!$H$2:$H$91),1) -> 8.7
...

Sheet Dashboard
A1: E-Governance Service Dashboard
A2: Citizen applications for government services | Data: Cleaned Data sheet | Use the filter arrows on the Cleaned Data sheet to explore records
A4: Total Applications | C4: Approval Rate (%) | E4: Approved | G4: Rejected | I4: Pending | K4: Avg Processing Days | M4: Avg Satisfaction
A5: =Calculations!B4 -> 90 | C5: =Calculations!B8 -> 73.3 | E5: =Calculations!B5 -> 66 | G5: =Calculations!B6 -> 7 | I5: =Calculations!B7 -> 17 | K5: =Calculations!B9 -> 7 | M5: =Calculations!B10 -> 3.73
